<?xml version="1.0"?>
<robot name="DEOSSIM">
    <link name="world">
    </link>
    <joint name="lwr_floating_base" type="floating">
                <origin xyz="0.0 0 0.0" rpy="0 0 0"/>
                <parent link="world"/>
                <child link="lwr_base_link"/>
				<axis xyz="1 1 1"/>
    </joint>
    <link name="lwr_base_link">				
                <tcp number="0" />
                <inertial>
                    <origin xyz="0.0 0 0.0" rpy="0 0 0"/>
                    <mass value="500"/>
					<inertia ixx="228.45" iyy="247.20" izz="221.25" ixy="0" ixz="0" iyz="0"/>                    
                </inertial>
                <visual>
                        <origin xyz="0 0 0" rpy="3.141592654 0 -0.5236"/>
                        <geometry>
                                <mesh filename="floating_base_stl/servicer_mockup.stl"/>
                        </geometry>
                </visual>
                <collision>
            <origin xyz="0 0 0" rpy="3.141592654 0 -0.5236"/>
            <geometry>
                     <mesh filename="floating_base_stl/servicer_mockup.stl"/>
            </geometry>
                </collision>
    </link>

    <joint name="lwr_joint_1" type="revolute">
                <origin xyz="0 0 0.11"  rpy="0 0 0"/>
                <parent link="lwr_base_link"/>
                <child link="lwr_link_1"/>
                <axis xyz="0 0 1"/>
    </joint>
    <link name="lwr_link_1">
                <inertial>
                    <origin xyz="0 0 0" rpy="0 0 0"/>
                        <mass value="2.7082"/>
                        <inertia ixx="0.0777" iyy="0.0774" izz="0.0058" ixy="0.0" ixz="0.0" iyz="-0.0086"/>
                </inertial>
                <visual>
                        <origin xyz="0 0 0.20" rpy="-1.570796327 0 0"/>
                        <geometry>
                                <mesh filename="floating_base_stl/lbr_kuka_link1.stl"/>
                        </geometry>
                </visual>
                <collision>
            <origin xyz="0 0 0.20" rpy="-1.570796327 0 0"/>
            <geometry>
               <mesh filename="floating_base_stl/lbr_kuka_link1.stl"/>
            </geometry>
                </collision>
    </link>


    <joint name="lwr_joint_2" type="revolute">
                <origin xyz="0 0 .2"  rpy="1.570796327 0 0"/>
                <parent link="lwr_link_1"/>
                <child link="lwr_link_2"/>
                <axis xyz="0 0 1"/>
    </joint>
    <link name="lwr_link_2">
                <inertial>
                    <origin xyz="0 0 0" rpy="0 0 0"/>
                        <mass value="2.7100"/>
                        <inertia ixx="0.0310" iyy="0.0053" izz="0.0311" ixy="-0.0001" ixz="0.0" iyz="0.0041"/>
                </inertial>
                <visual>
                        <origin xyz="0 0 0.0" rpy="-1.570796327 0 0"/>
                        <geometry>
                                <mesh filename="floating_base_stl/lbr_kuka_link2.stl"/>
                        </geometry>
                </visual>
                <collision>
                        <origin xyz="0 0 0.0" rpy="-1.570796327 0 0"/>
                        <geometry>
               <mesh filename="floating_base_stl/lbr_kuka_link2.stl"/>
            </geometry>
                </collision>
    </link>


    <joint name="lwr_joint_3" type="revolute">
                <origin xyz="0 .2 0"  rpy="-1.570796327 0 0"/>
                <parent link="lwr_link_2"/>
                <child link="lwr_link_3"/>
                <axis xyz="0 0 1"/>
    </joint>
    <link name="lwr_link_3">
                <inertial>
                    <origin xyz="0 0 0" rpy="0 0 0"/>
                        <mass value="2.5374"/>
                        <inertia ixx="0.1595" iyy="0.1595" izz="0.0049" ixy="0.0" ixz="-0.0002" iyz="0.0012"/>
                </inertial>
                <visual>
                        <origin xyz="0 0 0.2" rpy="-1.570796327 0 0"/>
                        <geometry>
                                <mesh filename="floating_base_stl/lbr_kuka_link3.stl"/>
                        </geometry>
                </visual>
                <collision>
                        <origin xyz="0 0 0.2" rpy="-1.570796327 0 0"/>
            <geometry>
               <mesh filename="floating_base_stl/lbr_kuka_link3.stl"/>
            </geometry>
                </collision>
    </link>


    <joint name="lwr_joint_4" type="revolute">
                <origin xyz="0 0 .2"  rpy="-1.570796327 0 0"/>
                <parent link="lwr_link_3"/>
                <child link="lwr_link_4"/>
                <axis xyz="0 0 1"/>
    </joint>
    <link name="lwr_link_4">
                <inertial>
                    <origin xyz="0 0 0" rpy="0 0 0"/>
                        <mass value="2.5053"/>
                        <inertia ixx="0.0333" iyy="0.0049" izz="0.0284" ixy="-0.0002" ixz="0.0" iyz="-0.0033"/>
                </inertial>
                <visual>
                        <origin xyz="0 0 0" rpy="-1.570796327 0 0"/>
                        <geometry>
                                <mesh filename="floating_base_stl/lbr_kuka_link4.stl"/>
                        </geometry>
                </visual>
                <collision>
                        <origin xyz="0 0 0" rpy="-1.570796327 0 0"/>
                        <geometry>
               <mesh filename="floating_base_stl/lbr_kuka_link4.stl"/>
            </geometry>
                </collision>
    </link>


    <joint name="lwr_joint_5" type="revolute">
                <origin xyz="0 -0.19 0"  rpy="1.570796327 0 0"/>
                <parent link="lwr_link_4"/>
                <child link="lwr_link_5"/>
                <axis xyz="0 0 1"/>
    </joint>
    <link name="lwr_link_5">
                <inertial>
                    <origin xyz="0 0 0" rpy="0 0 0"/>
                        <mass value="1.3028"/>
                        <inertia ixx="0.0852" iyy="0.0850" izz="0.0264" ixy="0.0" ixz="0.0001" iyz="-0.0069"/>
                </inertial>
                <visual>
                        <origin xyz="0 0 0.2" rpy="-1.570796327 0 0"/>
                        <geometry>
                                <mesh filename="floating_base_stl/lbr_kuka_link5.stl"/>
                        </geometry>
                </visual>
                <collision>
            <origin xyz="0 0 0.2" rpy="-1.570796327 0 0"/>
            <geometry>
               <mesh filename="floating_base_stl/lbr_kuka_link5.stl"/>
            </geometry>
                </collision>
    </link>

    <joint name="lwr_joint_6" type="revolute">
                <origin xyz="0 0 0.20"  rpy="1.570796327 0 0"/>
                <parent link="lwr_link_5"/>
                <child link="lwr_link_6"/>
                <axis xyz="0 0 1"/>
    </joint>
    <link name="lwr_link_6">
                <inertial>
                    <origin xyz="0 0 0" rpy="0 0 0"/>
                        <mass value="1.5686"/>
                        <inertia ixx="0.0043" iyy="0.0034" izz="0.0035" ixy="0.0" ixz="0.0" iyz="0.0005"/>
                </inertial>
                <visual>
                        <origin xyz="0 0 0" rpy="0 3.141592654 0"/>
                        <geometry>
                                <mesh filename="floating_base_stl/lbr_kuka_link6.stl"/>
                        </geometry>
                </visual>
                <collision>
                        <origin xyz="0 0 0" rpy="0 3.141592654 0"/>
                        <geometry>
               <mesh filename="floating_base_stl/lbr_kuka_link6.stl"/>
            </geometry>
                </collision>
    </link>


    <joint name="lwr_joint_7" type="revolute">
                <origin xyz="0 0 0"  rpy="-1.570796327 0 0"/>
                <parent link="lwr_link_6"/>
                <child link="lwr_link_7"/>
                <axis xyz="0 0 1"/>
    </joint>
    <link name="lwr_link_7">        
                <tcp number="1" />
                <inertial>
                    <origin xyz="0 0 0" rpy="0 0 0"/>
                        <mass value="3.8433"/>
                        <inertia ixx="0.1643" iyy="0.1819" izz="0.0730" ixy="-0.0007" ixz="0.0095" iyz="0.0041"/>
                </inertial>
            <visual>
                        <origin xyz="0 0 0" rpy="1.570796327 3.141592654 0"/>
                        <geometry>
                                <mesh filename="floating_base_stl/lbr_kuka_link7.stl"/>
                        </geometry>
                </visual>
    </link>

</robot>
